Process A: arrival time 33ms; tau 100ms; 14 CPU bursts:
--> CPU burst 207ms --> I/O burst 340ms
--> CPU burst 105ms --> I/O burst 120ms
--> CPU burst 226ms --> I/O burst 1720ms
--> CPU burst 64ms --> I/O burst 610ms
--> CPU burst 44ms --> I/O burst 650ms
--> CPU burst 110ms --> I/O burst 630ms
--> CPU burst 4ms --> I/O burst 70ms
--> CPU burst 11ms --> I/O burst 290ms
--> CPU burst 82ms --> I/O burst 1750ms
--> CPU burst 49ms --> I/O burst 3580ms
--> CPU burst 117ms --> I/O burst 160ms
--> CPU burst 73ms --> I/O burst 1600ms
--> CPU burst 117ms --> I/O burst 1070ms
--> CPU burst 69ms
Process B: arrival time 91ms; tau 100ms; 58 CPU bursts:
--> CPU burst 70ms --> I/O burst 2580ms
--> CPU burst 8ms --> I/O burst 470ms
--> CPU burst 15ms --> I/O burst 280ms
--> CPU burst 71ms --> I/O burst 280ms
--> CPU burst 69ms --> I/O burst 550ms
--> CPU burst 31ms --> I/O burst 1490ms
--> CPU burst 61ms --> I/O burst 110ms
--> CPU burst 73ms --> I/O burst 240ms
--> CPU burst 56ms --> I/O burst 960ms
--> CPU burst 32ms --> I/O burst 1610ms
--> CPU burst 79ms --> I/O burst 40ms
--> CPU burst 70ms --> I/O burst 2070ms
--> CPU burst 103ms --> I/O burst 1750ms
--> CPU burst 148ms --> I/O burst 760ms
--> CPU burst 63ms --> I/O burst 90ms
--> CPU burst 8ms --> I/O burst 1090ms
--> CPU burst 95ms --> I/O burst 1340ms
--> CPU burst 45ms --> I/O burst 710ms
--> CPU burst 142ms --> I/O burst 10ms
--> CPU burst 56ms --> I/O burst 340ms
--> CPU burst 6ms --> I/O burst 4650ms
--> CPU burst 209ms --> I/O burst 80ms
--> CPU burst 211ms --> I/O burst 1060ms
--> CPU burst 60ms --> I/O burst 910ms
--> CPU burst 46ms --> I/O burst 380ms
--> CPU burst 4ms --> I/O burst 150ms
--> CPU burst 6ms --> I/O burst 1090ms
--> CPU burst 24ms --> I/O burst 640ms
--> CPU burst 101ms --> I/O burst 910ms
--> CPU burst 98ms --> I/O burst 2510ms
--> CPU burst 78ms --> I/O burst 1060ms
--> CPU burst 49ms --> I/O burst 2970ms
--> CPU burst 93ms --> I/O burst 1190ms
--> CPU burst 347ms --> I/O burst 240ms
--> CPU burst 80ms --> I/O burst 2760ms
--> CPU burst 182ms --> I/O burst 230ms
--> CPU burst 415ms --> I/O burst 920ms
--> CPU burst 281ms --> I/O burst 620ms
--> CPU burst 77ms --> I/O burst 580ms
--> CPU burst 56ms --> I/O burst 660ms
--> CPU burst 53ms --> I/O burst 310ms
--> CPU burst 77ms --> I/O burst 1110ms
--> CPU burst 197ms --> I/O burst 1590ms
--> CPU burst 5ms --> I/O burst 370ms
--> CPU burst 65ms --> I/O burst 570ms
--> CPU burst 39ms --> I/O burst 1070ms
--> CPU burst 37ms --> I/O burst 370ms
--> CPU burst 49ms --> I/O burst 130ms
--> CPU burst 4ms --> I/O burst 890ms
--> CPU burst 3ms --> I/O burst 500ms
--> CPU burst 219ms --> I/O burst 2800ms
--> CPU burst 24ms --> I/O burst 1280ms
--> CPU burst 230ms --> I/O burst 600ms
--> CPU burst 26ms --> I/O burst 960ms
--> CPU burst 13ms --> I/O burst 530ms
--> CPU burst 163ms --> I/O burst 420ms
--> CPU burst 11ms --> I/O burst 420ms
--> CPU burst 158ms

time 0ms: Simulator started for FCFS [Q: empty]
time 33ms: Process A arrived; added to ready queue [Q: A]
time 35ms: Process A started using the CPU for 207ms burst [Q: empty]
time 91ms: Process B arrived; added to ready queue [Q: B]
time 242ms: Process A completed a CPU burst; 13 bursts to go [Q: B]
time 242ms: Process A switching out of CPU; will block on I/O until time 584ms [Q: B]
time 246ms: Process B started using the CPU for 70ms burst [Q: empty]
time 316ms: Process B completed a CPU burst; 57 bursts to go [Q: empty]
time 316ms: Process B switching out of CPU; will block on I/O until time 2898ms [Q: empty]
time 584ms: Process A completed I/O; added to ready queue [Q: A]
time 586ms: Process A started using the CPU for 105ms burst [Q: empty]
time 691ms: Process A completed a CPU burst; 12 bursts to go [Q: empty]
time 691ms: Process A switching out of CPU; will block on I/O until time 813ms [Q: empty]
time 813ms: Process A completed I/O; added to ready queue [Q: A]
time 815ms: Process A started using the CPU for 226ms burst [Q: empty]
time 1041ms: Process A completed a CPU burst; 11 bursts to go [Q: empty]
time 1041ms: Process A switching out of CPU; will block on I/O until time 2763ms [Q: empty]
time 2763ms: Process A completed I/O; added to ready queue [Q: A]
time 2765ms: Process A started using the CPU for 64ms burst [Q: empty]
time 2829ms: Process A completed a CPU burst; 10 bursts to go [Q: empty]
time 2829ms: Process A switching out of CPU; will block on I/O until time 3441ms [Q: empty]
time 2898ms: Process B completed I/O; added to ready queue [Q: B]
time 2900ms: Process B started using the CPU for 8ms burst [Q: empty]
time 2908ms: Process B completed a CPU burst; 56 bursts to go [Q: empty]
time 2908ms: Process B switching out of CPU; will block on I/O until time 3380ms [Q: empty]
time 3380ms: Process B completed I/O; added to ready queue [Q: B]
time 3382ms: Process B started using the CPU for 15ms burst [Q: empty]
time 3397ms: Process B completed a CPU burst; 55 bursts to go [Q: empty]
time 3397ms: Process B switching out of CPU; will block on I/O until time 3679ms [Q: empty]
time 3441ms: Process A completed I/O; added to ready queue [Q: A]
time 3443ms: Process A started using the CPU for 44ms burst [Q: empty]
time 3487ms: Process A completed a CPU burst; 9 bursts to go [Q: empty]
time 3487ms: Process A switching out of CPU; will block on I/O until time 4139ms [Q: empty]
time 3679ms: Process B completed I/O; added to ready queue [Q: B]
time 3681ms: Process B started using the CPU for 71ms burst [Q: empty]
time 3752ms: Process B completed a CPU burst; 54 bursts to go [Q: empty]
time 3752ms: Process B switching out of CPU; will block on I/O until time 4034ms [Q: empty]
time 4034ms: Process B completed I/O; added to ready queue [Q: B]
time 4036ms: Process B started using the CPU for 69ms burst [Q: empty]
time 4105ms: Process B completed a CPU burst; 53 bursts to go [Q: empty]
time 4105ms: Process B switching out of CPU; will block on I/O until time 4657ms [Q: empty]
time 4139ms: Process A completed I/O; added to ready queue [Q: A]
time 4141ms: Process A started using the CPU for 110ms burst [Q: empty]
time 4251ms: Process A completed a CPU burst; 8 bursts to go [Q: empty]
time 4251ms: Process A switching out of CPU; will block on I/O until time 4883ms [Q: empty]
time 4657ms: Process B completed I/O; added to ready queue [Q: B]
time 4659ms: Process B started using the CPU for 31ms burst [Q: empty]
time 4690ms: Process B completed a CPU burst; 52 bursts to go [Q: empty]
time 4690ms: Process B switching out of CPU; will block on I/O until time 6182ms [Q: empty]
time 4883ms: Process A completed I/O; added to ready queue [Q: A]
time 4885ms: Process A started using the CPU for 4ms burst [Q: empty]
time 4889ms: Process A completed a CPU burst; 7 bursts to go [Q: empty]
time 4889ms: Process A switching out of CPU; will block on I/O until time 4961ms [Q: empty]
time 4961ms: Process A completed I/O; added to ready queue [Q: A]
time 4963ms: Process A started using the CPU for 11ms burst [Q: empty]
time 4974ms: Process A completed a CPU burst; 6 bursts to go [Q: empty]
time 4974ms: Process A switching out of CPU; will block on I/O until time 5266ms [Q: empty]
time 5266ms: Process A completed I/O; added to ready queue [Q: A]
time 5268ms: Process A started using the CPU for 82ms burst [Q: empty]
time 5350ms: Process A completed a CPU burst; 5 bursts to go [Q: empty]
time 5350ms: Process A switching out of CPU; will block on I/O until time 7102ms [Q: empty]
time 6182ms: Process B completed I/O; added to ready queue [Q: B]
time 6184ms: Process B started using the CPU for 61ms burst [Q: empty]
time 6245ms: Process B completed a CPU burst; 51 bursts to go [Q: empty]
time 6245ms: Process B switching out of CPU; will block on I/O until time 6357ms [Q: empty]
time 6357ms: Process B completed I/O; added to ready queue [Q: B]
time 6359ms: Process B started using the CPU for 73ms burst [Q: empty]
time 6432ms: Process B completed a CPU burst; 50 bursts to go [Q: empty]
time 6432ms: Process B switching out of CPU; will block on I/O until time 6674ms [Q: empty]
time 6674ms: Process B completed I/O; added to ready queue [Q: B]
time 6676ms: Process B started using the CPU for 56ms burst [Q: empty]
time 6732ms: Process B completed a CPU burst; 49 bursts to go [Q: empty]
time 6732ms: Process B switching out of CPU; will block on I/O until time 7694ms [Q: empty]
time 7102ms: Process A completed I/O; added to ready queue [Q: A]
time 7104ms: Process A started using the CPU for 49ms burst [Q: empty]
time 7153ms: Process A completed a CPU burst; 4 bursts to go [Q: empty]
time 7153ms: Process A switching out of CPU; will block on I/O until time 10735ms [Q: empty]
time 7694ms: Process B completed I/O; added to ready queue [Q: B]
time 7696ms: Process B started using the CPU for 32ms burst [Q: empty]
time 7728ms: Process B completed a CPU burst; 48 bursts to go [Q: empty]
time 7728ms: Process B switching out of CPU; will block on I/O until time 9340ms [Q: empty]
time 9340ms: Process B completed I/O; added to ready queue [Q: B]
time 9342ms: Process B started using the CPU for 79ms burst [Q: empty]
time 9421ms: Process B completed a CPU burst; 47 bursts to go [Q: empty]
time 9421ms: Process B switching out of CPU; will block on I/O until time 9463ms [Q: empty]
time 9463ms: Process B completed I/O; added to ready queue [Q: B]
time 9465ms: Process B started using the CPU for 70ms burst [Q: empty]
time 9535ms: Process B completed a CPU burst; 46 bursts to go [Q: empty]
time 9535ms: Process B switching out of CPU; will block on I/O until time 11607ms [Q: empty]
time 10735ms: Process A completed I/O; added to ready queue [Q: A]
time 10737ms: Process A started using the CPU for 117ms burst [Q: empty]
time 10854ms: Process A completed a CPU burst; 3 bursts to go [Q: empty]
time 10854ms: Process A switching out of CPU; will block on I/O until time 11016ms [Q: empty]
time 11016ms: Process A completed I/O; added to ready queue [Q: A]
time 11018ms: Process A started using the CPU for 73ms burst [Q: empty]
time 11091ms: Process A completed a CPU burst; 2 bursts to go [Q: empty]
time 11091ms: Process A switching out of CPU; will block on I/O until time 12693ms [Q: empty]
time 11607ms: Process B completed I/O; added to ready queue [Q: B]
time 11609ms: Process B started using the CPU for 103ms burst [Q: empty]
time 11712ms: Process B completed a CPU burst; 45 bursts to go [Q: empty]
time 11712ms: Process B switching out of CPU; will block on I/O until time 13464ms [Q: empty]
time 12693ms: Process A completed I/O; added to ready queue [Q: A]
time 12695ms: Process A started using the CPU for 117ms burst [Q: empty]
time 12812ms: Process A completed a CPU burst; 1 bursts to go [Q: empty]
time 12812ms: Process A switching out of CPU; will block on I/O until time 13884ms [Q: empty]
time 13464ms: Process B completed I/O; added to ready queue [Q: B]
time 13466ms: Process B started using the CPU for 148ms burst [Q: empty]
time 13614ms: Process B completed a CPU burst; 44 bursts to go [Q: empty]
time 13614ms: Process B switching out of CPU; will block on I/O until time 14376ms [Q: empty]
time 13884ms: Process A completed I/O; added to ready queue [Q: A]
time 13886ms: Process A started using the CPU for 69ms burst [Q: empty]
time 13955ms: Process A terminated [Q: empty]
time 14376ms: Process B completed I/O; added to ready queue [Q: B]
time 14378ms: Process B started using the CPU for 63ms burst [Q: empty]
time 14441ms: Process B completed a CPU burst; 43 bursts to go [Q: empty]
time 14441ms: Process B switching out of CPU; will block on I/O until time 14533ms [Q: empty]
time 14533ms: Process B completed I/O; added to ready queue [Q: B]
time 14535ms: Process B started using the CPU for 8ms burst [Q: empty]
time 14543ms: Process B completed a CPU burst; 42 bursts to go [Q: empty]
time 14543ms: Process B switching out of CPU; will block on I/O until time 15635ms [Q: empty]
time 15635ms: Process B completed I/O; added to ready queue [Q: B]
time 15637ms: Process B started using the CPU for 95ms burst [Q: empty]
time 15732ms: Process B completed a CPU burst; 41 bursts to go [Q: empty]
time 15732ms: Process B switching out of CPU; will block on I/O until time 17074ms [Q: empty]
time 17074ms: Process B completed I/O; added to ready queue [Q: B]
time 17076ms: Process B started using the CPU for 45ms burst [Q: empty]
time 17121ms: Process B completed a CPU burst; 40 bursts to go [Q: empty]
time 17121ms: Process B switching out of CPU; will block on I/O until time 17833ms [Q: empty]
time 17833ms: Process B completed I/O; added to ready queue [Q: B]
time 17835ms: Process B started using the CPU for 142ms burst [Q: empty]
time 17977ms: Process B completed a CPU burst; 39 bursts to go [Q: empty]
time 17977ms: Process B switching out of CPU; will block on I/O until time 17989ms [Q: empty]
time 17989ms: Process B completed I/O; added to ready queue [Q: B]
time 17991ms: Process B started using the CPU for 56ms burst [Q: empty]
time 18047ms: Process B completed a CPU burst; 38 bursts to go [Q: empty]
time 18047ms: Process B switching out of CPU; will block on I/O until time 18389ms [Q: empty]
time 18389ms: Process B completed I/O; added to ready queue [Q: B]
time 18391ms: Process B started using the CPU for 6ms burst [Q: empty]
time 18397ms: Process B completed a CPU burst; 37 bursts to go [Q: empty]
time 18397ms: Process B switching out of CPU; will block on I/O until time 23049ms [Q: empty]
time 23049ms: Process B completed I/O; added to ready queue [Q: B]
time 23051ms: Process B started using the CPU for 209ms burst [Q: empty]
time 23260ms: Process B completed a CPU burst; 36 bursts to go [Q: empty]
time 23260ms: Process B switching out of CPU; will block on I/O until time 23342ms [Q: empty]
time 23342ms: Process B completed I/O; added to ready queue [Q: B]
time 23344ms: Process B started using the CPU for 211ms burst [Q: empty]
time 23555ms: Process B completed a CPU burst; 35 bursts to go [Q: empty]
time 23555ms: Process B switching out of CPU; will block on I/O until time 24617ms [Q: empty]
time 24617ms: Process B completed I/O; added to ready queue [Q: B]
time 24619ms: Process B started using the CPU for 60ms burst [Q: empty]
time 24679ms: Process B completed a CPU burst; 34 bursts to go [Q: empty]
time 24679ms: Process B switching out of CPU; will block on I/O until time 25591ms [Q: empty]
time 25591ms: Process B completed I/O; added to ready queue [Q: B]
time 25593ms: Process B started using the CPU for 46ms burst [Q: empty]
time 25639ms: Process B completed a CPU burst; 33 bursts to go [Q: empty]
time 25639ms: Process B switching out of CPU; will block on I/O until time 26021ms [Q: empty]
time 26021ms: Process B completed I/O; added to ready queue [Q: B]
time 26023ms: Process B started using the CPU for 4ms burst [Q: empty]
time 26027ms: Process B completed a CPU burst; 32 bursts to go [Q: empty]
time 26027ms: Process B switching out of CPU; will block on I/O until time 26179ms [Q: empty]
time 26179ms: Process B completed I/O; added to ready queue [Q: B]
time 26181ms: Process B started using the CPU for 6ms burst [Q: empty]
time 26187ms: Process B completed a CPU burst; 31 bursts to go [Q: empty]
time 26187ms: Process B switching out of CPU; will block on I/O until time 27279ms [Q: empty]
time 27279ms: Process B completed I/O; added to ready queue [Q: B]
time 27281ms: Process B started using the CPU for 24ms burst [Q: empty]
time 27305ms: Process B completed a CPU burst; 30 bursts to go [Q: empty]
time 27305ms: Process B switching out of CPU; will block on I/O until time 27947ms [Q: empty]
time 27947ms: Process B completed I/O; added to ready queue [Q: B]
time 27949ms: Process B started using the CPU for 101ms burst [Q: empty]
time 28050ms: Process B completed a CPU burst; 29 bursts to go [Q: empty]
time 28050ms: Process B switching out of CPU; will block on I/O until time 28962ms [Q: empty]
time 28962ms: Process B completed I/O; added to ready queue [Q: B]
time 28964ms: Process B started using the CPU for 98ms burst [Q: empty]
time 29062ms: Process B completed a CPU burst; 28 bursts to go [Q: empty]
time 29062ms: Process B switching out of CPU; will block on I/O until time 31574ms [Q: empty]
time 31574ms: Process B completed I/O; added to ready queue [Q: B]
time 31576ms: Process B started using the CPU for 78ms burst [Q: empty]
time 31654ms: Process B completed a CPU burst; 27 bursts to go [Q: empty]
time 31654ms: Process B switching out of CPU; will block on I/O until time 32716ms [Q: empty]
time 32716ms: Process B completed I/O; added to ready queue [Q: B]
time 32718ms: Process B started using the CPU for 49ms burst [Q: empty]
time 32767ms: Process B completed a CPU burst; 26 bursts to go [Q: empty]
time 32767ms: Process B switching out of CPU; will block on I/O until time 35739ms [Q: empty]
time 35739ms: Process B completed I/O; added to ready queue [Q: B]
time 35741ms: Process B started using the CPU for 93ms burst [Q: empty]
time 35834ms: Process B completed a CPU burst; 25 bursts to go [Q: empty]
time 35834ms: Process B switching out of CPU; will block on I/O until time 37026ms [Q: empty]
time 37026ms: Process B completed I/O; added to ready queue [Q: B]
time 37028ms: Process B started using the CPU for 347ms burst [Q: empty]
time 37375ms: Process B completed a CPU burst; 24 bursts to go [Q: empty]
time 37375ms: Process B switching out of CPU; will block on I/O until time 37617ms [Q: empty]
time 37617ms: Process B completed I/O; added to ready queue [Q: B]
time 37619ms: Process B started using the CPU for 80ms burst [Q: empty]
time 37699ms: Process B completed a CPU burst; 23 bursts to go [Q: empty]
time 37699ms: Process B switching out of CPU; will block on I/O until time 40461ms [Q: empty]
time 40461ms: Process B completed I/O; added to ready queue [Q: B]
time 40463ms: Process B started using the CPU for 182ms burst [Q: empty]
time 40645ms: Process B completed a CPU burst; 22 bursts to go [Q: empty]
time 40645ms: Process B switching out of CPU; will block on I/O until time 40877ms [Q: empty]
time 40877ms: Process B completed I/O; added to ready queue [Q: B]
time 40879ms: Process B started using the CPU for 415ms burst [Q: empty]
time 41294ms: Process B completed a CPU burst; 21 bursts to go [Q: empty]
time 41294ms: Process B switching out of CPU; will block on I/O until time 42216ms [Q: empty]
time 42216ms: Process B completed I/O; added to ready queue [Q: B]
time 42218ms: Process B started using the CPU for 281ms burst [Q: empty]
time 42499ms: Process B completed a CPU burst; 20 bursts to go [Q: empty]
time 42499ms: Process B switching out of CPU; will block on I/O until time 43121ms [Q: empty]
time 43121ms: Process B completed I/O; added to ready queue [Q: B]
time 43123ms: Process B started using the CPU for 77ms burst [Q: empty]
time 43200ms: Process B completed a CPU burst; 19 bursts to go [Q: empty]
time 43200ms: Process B switching out of CPU; will block on I/O until time 43782ms [Q: empty]
time 43782ms: Process B completed I/O; added to ready queue [Q: B]
time 43784ms: Process B started using the CPU for 56ms burst [Q: empty]
time 43840ms: Process B completed a CPU burst; 18 bursts to go [Q: empty]
time 43840ms: Process B switching out of CPU; will block on I/O until time 44502ms [Q: empty]
time 44502ms: Process B completed I/O; added to ready queue [Q: B]
time 44504ms: Process B started using the CPU for 53ms burst [Q: empty]
time 44557ms: Process B completed a CPU burst; 17 bursts to go [Q: empty]
time 44557ms: Process B switching out of CPU; will block on I/O until time 44869ms [Q: empty]
time 44869ms: Process B completed I/O; added to ready queue [Q: B]
time 44871ms: Process B started using the CPU for 77ms burst [Q: empty]
time 44948ms: Process B completed a CPU burst; 16 bursts to go [Q: empty]
time 44948ms: Process B switching out of CPU; will block on I/O until time 46060ms [Q: empty]
time 46060ms: Process B completed I/O; added to ready queue [Q: B]
time 46062ms: Process B started using the CPU for 197ms burst [Q: empty]
time 46259ms: Process B completed a CPU burst; 15 bursts to go [Q: empty]
time 46259ms: Process B switching out of CPU; will block on I/O until time 47851ms [Q: empty]
time 47851ms: Process B completed I/O; added to ready queue [Q: B]
time 47853ms: Process B started using the CPU for 5ms burst [Q: empty]
time 47858ms: Process B completed a CPU burst; 14 bursts to go [Q: empty]
time 47858ms: Process B switching out of CPU; will block on I/O until time 48230ms [Q: empty]
time 48230ms: Process B completed I/O; added to ready queue [Q: B]
time 48232ms: Process B started using the CPU for 65ms burst [Q: empty]
time 48297ms: Process B completed a CPU burst; 13 bursts to go [Q: empty]
time 48297ms: Process B switching out of CPU; will block on I/O until time 48869ms [Q: empty]
time 48869ms: Process B completed I/O; added to ready queue [Q: B]
time 48871ms: Process B started using the CPU for 39ms burst [Q: empty]
time 48910ms: Process B completed a CPU burst; 12 bursts to go [Q: empty]
time 48910ms: Process B switching out of CPU; will block on I/O until time 49982ms [Q: empty]
time 49982ms: Process B completed I/O; added to ready queue [Q: B]
time 49984ms: Process B started using the CPU for 37ms burst [Q: empty]
time 50021ms: Process B completed a CPU burst; 11 bursts to go [Q: empty]
time 50021ms: Process B switching out of CPU; will block on I/O until time 50393ms [Q: empty]
time 50393ms: Process B completed I/O; added to ready queue [Q: B]
time 50395ms: Process B started using the CPU for 49ms burst [Q: empty]
time 50444ms: Process B completed a CPU burst; 10 bursts to go [Q: empty]
time 50444ms: Process B switching out of CPU; will block on I/O until time 50576ms [Q: empty]
time 50576ms: Process B completed I/O; added to ready queue [Q: B]
time 50578ms: Process B started using the CPU for 4ms burst [Q: empty]
time 50582ms: Process B completed a CPU burst; 9 bursts to go [Q: empty]
time 50582ms: Process B switching out of CPU; will block on I/O until time 51474ms [Q: empty]
time 51474ms: Process B completed I/O; added to ready queue [Q: B]
time 51476ms: Process B started using the CPU for 3ms burst [Q: empty]
time 51479ms: Process B completed a CPU burst; 8 bursts to go [Q: empty]
time 51479ms: Process B switching out of CPU; will block on I/O until time 51981ms [Q: empty]
time 51981ms: Process B completed I/O; added to ready queue [Q: B]
time 51983ms: Process B started using the CPU for 219ms burst [Q: empty]
time 52202ms: Process B completed a CPU burst; 7 bursts to go [Q: empty]
time 52202ms: Process B switching out of CPU; will block on I/O until time 55004ms [Q: empty]
time 55004ms: Process B completed I/O; added to ready queue [Q: B]
time 55006ms: Process B started using the CPU for 24ms burst [Q: empty]
time 55030ms: Process B completed a CPU burst; 6 bursts to go [Q: empty]
time 55030ms: Process B switching out of CPU; will block on I/O until time 56312ms [Q: empty]
time 56312ms: Process B completed I/O; added to ready queue [Q: B]
time 56314ms: Process B started using the CPU for 230ms burst [Q: empty]
time 56544ms: Process B completed a CPU burst; 5 bursts to go [Q: empty]
time 56544ms: Process B switching out of CPU; will block on I/O until time 57146ms [Q: empty]
time 57146ms: Process B completed I/O; added to ready queue [Q: B]
time 57148ms: Process B started using the CPU for 26ms burst [Q: empty]
time 57174ms: Process B completed a CPU burst; 4 bursts to go [Q: empty]
time 57174ms: Process B switching out of CPU; will block on I/O until time 58136ms [Q: empty]
time 58136ms: Process B completed I/O; added to ready queue [Q: B]
time 58138ms: Process B started using the CPU for 13ms burst [Q: empty]
time 58151ms: Process B completed a CPU burst; 3 bursts to go [Q: empty]
time 58151ms: Process B switching out of CPU; will block on I/O until time 58683ms [Q: empty]
time 58683ms: Process B completed I/O; added to ready queue [Q: B]
time 58685ms: Process B started using the CPU for 163ms burst [Q: empty]
time 58848ms: Process B completed a CPU burst; 2 bursts to go [Q: empty]
time 58848ms: Process B switching out of CPU; will block on I/O until time 59270ms [Q: empty]
time 59270ms: Process B completed I/O; added to ready queue [Q: B]
time 59272ms: Process B started using the CPU for 11ms burst [Q: empty]
time 59283ms: Process B completed a CPU burst; 1 bursts to go [Q: empty]
time 59283ms: Process B switching out of CPU; will block on I/O until time 59705ms [Q: empty]
time 59705ms: Process B completed I/O; added to ready queue [Q: B]
time 59707ms: Process B started using the CPU for 158ms burst [Q: empty]
time 59865ms: Process B terminated [Q: empty]
time 59867ms: Simulator ended for FCFS [Q: empty]

time 0ms: Simulator started for SJF [Q: empty]
time 33ms: Process A (tau 100ms) arrived; added to ready queue [Q: A]
time 35ms: Process A (tau 100ms) started using the CPU for 207ms burst [Q: empty]
time 91ms: Process B (tau 100ms) arrived; added to ready queue [Q: B]
time 242ms: Process A (tau 100ms) completed a CPU burst; 13 bursts to go [Q: B]
time 242ms: Recalculated tau for process A: old tau 100ms; new tau 154ms [Q: B]
time 242ms: Process A switching out of CPU; will block on I/O until time 584ms [Q: B]
time 246ms: Process B (tau 100ms) started using the CPU for 70ms burst [Q: empty]
time 316ms: Process B (tau 100ms) completed a CPU burst; 57 bursts to go [Q: empty]
time 316ms: Recalculated tau for process B: old tau 100ms; new tau 85ms [Q: empty]
time 316ms: Process B switching out of CPU; will block on I/O until time 2898ms [Q: empty]
time 584ms: Process A (tau 154ms) completed I/O; added to ready queue [Q: A]
time 586ms: Process A (tau 154ms) started using the CPU for 105ms burst [Q: empty]
time 691ms: Process A (tau 154ms) completed a CPU burst; 12 bursts to go [Q: empty]
time 691ms: Recalculated tau for process A: old tau 154ms; new tau 130ms [Q: empty]
time 691ms: Process A switching out of CPU; will block on I/O until time 813ms [Q: empty]
time 813ms: Process A (tau 130ms) completed I/O; added to ready queue [Q: A]
time 815ms: Process A (tau 130ms) started using the CPU for 226ms burst [Q: empty]
time 1041ms: Process A (tau 130ms) completed a CPU burst; 11 bursts to go [Q: empty]
time 1041ms: Recalculated tau for process A: old tau 130ms; new tau 178ms [Q: empty]
time 1041ms: Process A switching out of CPU; will block on I/O until time 2763ms [Q: empty]
time 2763ms: Process A (tau 178ms) completed I/O; added to ready queue [Q: A]
time 2765ms: Process A (tau 178ms) started using the CPU for 64ms burst [Q: empty]
time 2829ms: Process A (tau 178ms) completed a CPU burst; 10 bursts to go [Q: empty]
time 2829ms: Recalculated tau for process A: old tau 178ms; new tau 121ms [Q: empty]
time 2829ms: Process A switching out of CPU; will block on I/O until time 3441ms [Q: empty]
time 2898ms: Process B (tau 85ms) completed I/O; added to ready queue [Q: B]
time 2900ms: Process B (tau 85ms) started using the CPU for 8ms burst [Q: empty]
time 2908ms: Process B (tau 85ms) completed a CPU burst; 56 bursts to go [Q: empty]
time 2908ms: Recalculated tau for process B: old tau 85ms; new tau 47ms [Q: empty]
time 2908ms: Process B switching out of CPU; will block on I/O until time 3380ms [Q: empty]
time 3380ms: Process B (tau 47ms) completed I/O; added to ready queue [Q: B]
time 3382ms: Process B (tau 47ms) started using the CPU for 15ms burst [Q: empty]
time 3397ms: Process B (tau 47ms) completed a CPU burst; 55 bursts to go [Q: empty]
time 3397ms: Recalculated tau for process B: old tau 47ms; new tau 31ms [Q: empty]
time 3397ms: Process B switching out of CPU; will block on I/O until time 3679ms [Q: empty]
time 3441ms: Process A (tau 121ms) completed I/O; added to ready queue [Q: A]
time 3443ms: Process A (tau 121ms) started using the CPU for 44ms burst [Q: empty]
time 3487ms: Process A (tau 121ms) completed a CPU burst; 9 bursts to go [Q: empty]
time 3487ms: Recalculated tau for process A: old tau 121ms; new tau 83ms [Q: empty]
time 3487ms: Process A switching out of CPU; will block on I/O until time 4139ms [Q: empty]
time 3679ms: Process B (tau 31ms) completed I/O; added to ready queue [Q: B]
time 3681ms: Process B (tau 31ms) started using the CPU for 71ms burst [Q: empty]
time 3752ms: Process B (tau 31ms) completed a CPU burst; 54 bursts to go [Q: empty]
time 3752ms: Recalculated tau for process B: old tau 31ms; new tau 51ms [Q: empty]
time 3752ms: Process B switching out of CPU; will block on I/O until time 4034ms [Q: empty]
time 4034ms: Process B (tau 51ms) completed I/O; added to ready queue [Q: B]
time 4036ms: Process B (tau 51ms) started using the CPU for 69ms burst [Q: empty]
time 4105ms: Process B (tau 51ms) completed a CPU burst; 53 bursts to go [Q: empty]
time 4105ms: Recalculated tau for process B: old tau 51ms; new tau 60ms [Q: empty]
time 4105ms: Process B switching out of CPU; will block on I/O until time 4657ms [Q: empty]
time 4139ms: Process A (tau 83ms) completed I/O; added to ready queue [Q: A]
time 4141ms: Process A (tau 83ms) started using the CPU for 110ms burst [Q: empty]
time 4251ms: Process A (tau 83ms) completed a CPU burst; 8 bursts to go [Q: empty]
time 4251ms: Recalculated tau for process A: old tau 83ms; new tau 97ms [Q: empty]
time 4251ms: Process A switching out of CPU; will block on I/O until time 4883ms [Q: empty]
time 4657ms: Process B (tau 60ms) completed I/O; added to ready queue [Q: B]
time 4659ms: Process B (tau 60ms) started using the CPU for 31ms burst [Q: empty]
time 4690ms: Process B (tau 60ms) completed a CPU burst; 52 bursts to go [Q: empty]
time 4690ms: Recalculated tau for process B: old tau 60ms; new tau 46ms [Q: empty]
time 4690ms: Process B switching out of CPU; will block on I/O until time 6182ms [Q: empty]
time 4883ms: Process A (tau 97ms) completed I/O; added to ready queue [Q: A]
time 4885ms: Process A (tau 97ms) started using the CPU for 4ms burst [Q: empty]
time 4889ms: Process A (tau 97ms) completed a CPU burst; 7 bursts to go [Q: empty]
time 4889ms: Recalculated tau for process A: old tau 97ms; new tau 51ms [Q: empty]
time 4889ms: Process A switching out of CPU; will block on I/O until time 4961ms [Q: empty]
time 4961ms: Process A (tau 51ms) completed I/O; added to ready queue [Q: A]
time 4963ms: Process A (tau 51ms) started using the CPU for 11ms burst [Q: empty]
time 4974ms: Process A (tau 51ms) completed a CPU burst; 6 bursts to go [Q: empty]
time 4974ms: Recalculated tau for process A: old tau 51ms; new tau 31ms [Q: empty]
time 4974ms: Process A switching out of CPU; will block on I/O until time 5266ms [Q: empty]
time 5266ms: Process A (tau 31ms) completed I/O; added to ready queue [Q: A]
time 5268ms: Process A (tau 31ms) started using the CPU for 82ms burst [Q: empty]
time 5350ms: Process A (tau 31ms) completed a CPU burst; 5 bursts to go [Q: empty]
time 5350ms: Recalculated tau for process A: old tau 31ms; new tau 57ms [Q: empty]
time 5350ms: Process A switching out of CPU; will block on I/O until time 7102ms [Q: empty]
time 6182ms: Process B (tau 46ms) completed I/O; added to ready queue [Q: B]
time 6184ms: Process B (tau 46ms) started using the CPU for 61ms burst [Q: empty]
time 6245ms: Process B (tau 46ms) completed a CPU burst; 51 bursts to go [Q: empty]
time 6245ms: Recalculated tau for process B: old tau 46ms; new tau 54ms [Q: empty]
time 6245ms: Process B switching out of CPU; will block on I/O until time 6357ms [Q: empty]
time 6357ms: Process B (tau 54ms) completed I/O; added to ready queue [Q: B]
time 6359ms: Process B (tau 54ms) started using the CPU for 73ms burst [Q: empty]
time 6432ms: Process B (tau 54ms) completed a CPU burst; 50 bursts to go [Q: empty]
time 6432ms: Recalculated tau for process B: old tau 54ms; new tau 64ms [Q: empty]
time 6432ms: Process B switching out of CPU; will block on I/O until time 6674ms [Q: empty]
time 6674ms: Process B (tau 64ms) completed I/O; added to ready queue [Q: B]
time 6676ms: Process B (tau 64ms) started using the CPU for 56ms burst [Q: empty]
time 6732ms: Process B (tau 64ms) completed a CPU burst; 49 bursts to go [Q: empty]
time 6732ms: Recalculated tau for process B: old tau 64ms; new tau 60ms [Q: empty]
time 6732ms: Process B switching out of CPU; will block on I/O until time 7694ms [Q: empty]
time 7102ms: Process A (tau 57ms) completed I/O; added to ready queue [Q: A]
time 7104ms: Process A (tau 57ms) started using the CPU for 49ms burst [Q: empty]
time 7153ms: Process A (tau 57ms) completed a CPU burst; 4 bursts to go [Q: empty]
time 7153ms: Recalculated tau for process A: old tau 57ms; new tau 53ms [Q: empty]
time 7153ms: Process A switching out of CPU; will block on I/O until time 10735ms [Q: empty]
time 7694ms: Process B (tau 60ms) completed I/O; added to ready queue [Q: B]
time 7696ms: Process B (tau 60ms) started using the CPU for 32ms burst [Q: empty]
time 7728ms: Process B (tau 60ms) completed a CPU burst; 48 bursts to go [Q: empty]
time 7728ms: Recalculated tau for process B: old tau 60ms; new tau 46ms [Q: empty]
time 7728ms: Process B switching out of CPU; will block on I/O until time 9340ms [Q: empty]
time 9340ms: Process B (tau 46ms) completed I/O; added to ready queue [Q: B]
time 9342ms: Process B (tau 46ms) started using the CPU for 79ms burst [Q: empty]
time 9421ms: Process B (tau 46ms) completed a CPU burst; 47 bursts to go [Q: empty]
time 9421ms: Recalculated tau for process B: old tau 46ms; new tau 63ms [Q: empty]
time 9421ms: Process B switching out of CPU; will block on I/O until time 9463ms [Q: empty]
time 9463ms: Process B (tau 63ms) completed I/O; added to ready queue [Q: B]
time 9465ms: Process B (tau 63ms) started using the CPU for 70ms burst [Q: empty]
time 9535ms: Process B (tau 63ms) completed a CPU burst; 46 bursts to go [Q: empty]
time 9535ms: Recalculated tau for process B: old tau 63ms; new tau 67ms [Q: empty]
time 9535ms: Process B switching out of CPU; will block on I/O until time 11607ms [Q: empty]
time 10735ms: Process A (tau 53ms) completed I/O; added to ready queue [Q: A]
time 10737ms: Process A (tau 53ms) started using the CPU for 117ms burst [Q: empty]
time 10854ms: Process A (tau 53ms) completed a CPU burst; 3 bursts to go [Q: empty]
time 10854ms: Recalculated tau for process A: old tau 53ms; new tau 85ms [Q: empty]
time 10854ms: Process A switching out of CPU; will block on I/O until time 11016ms [Q: empty]
time 11016ms: Process A (tau 85ms) completed I/O; added to ready queue [Q: A]
time 11018ms: Process A (tau 85ms) started using the CPU for 73ms burst [Q: empty]
time 11091ms: Process A (tau 85ms) completed a CPU burst; 2 bursts to go [Q: empty]
time 11091ms: Recalculated tau for process A: old tau 85ms; new tau 79ms [Q: empty]
time 11091ms: Process A switching out of CPU; will block on I/O until time 12693ms [Q: empty]
time 11607ms: Process B (tau 67ms) completed I/O; added to ready queue [Q: B]
time 11609ms: Process B (tau 67ms) started using the CPU for 103ms burst [Q: empty]
time 11712ms: Process B (tau 67ms) completed a CPU burst; 45 bursts to go [Q: empty]
time 11712ms: Recalculated tau for process B: old tau 67ms; new tau 85ms [Q: empty]
time 11712ms: Process B switching out of CPU; will block on I/O until time 13464ms [Q: empty]
time 12693ms: Process A (tau 79ms) completed I/O; added to ready queue [Q: A]
time 12695ms: Process A (tau 79ms) started using the CPU for 117ms burst [Q: empty]
time 12812ms: Process A (tau 79ms) completed a CPU burst; 1 bursts to go [Q: empty]
time 12812ms: Recalculated tau for process A: old tau 79ms; new tau 98ms [Q: empty]
time 12812ms: Process A switching out of CPU; will block on I/O until time 13884ms [Q: empty]
time 13464ms: Process B (tau 85ms) completed I/O; added to ready queue [Q: B]
time 13466ms: Process B (tau 85ms) started using the CPU for 148ms burst [Q: empty]
time 13614ms: Process B (tau 85ms) completed a CPU burst; 44 bursts to go [Q: empty]
time 13614ms: Recalculated tau for process B: old tau 85ms; new tau 117ms [Q: empty]
time 13614ms: Process B switching out of CPU; will block on I/O until time 14376ms [Q: empty]
time 13884ms: Process A (tau 98ms) completed I/O; added to ready queue [Q: A]
time 13886ms: Process A (tau 98ms) started using the CPU for 69ms burst [Q: empty]
time 13955ms: Process A terminated [Q: empty]
time 14376ms: Process B (tau 117ms) completed I/O; added to ready queue [Q: B]
time 14378ms: Process B (tau 117ms) started using the CPU for 63ms burst [Q: empty]
time 14441ms: Process B (tau 117ms) completed a CPU burst; 43 bursts to go [Q: empty]
time 14441ms: Recalculated tau for process B: old tau 117ms; new tau 90ms [Q: empty]
time 14441ms: Process B switching out of CPU; will block on I/O until time 14533ms [Q: empty]
time 14533ms: Process B (tau 90ms) completed I/O; added to ready queue [Q: B]
time 14535ms: Process B (tau 90ms) started using the CPU for 8ms burst [Q: empty]
time 14543ms: Process B (tau 90ms) completed a CPU burst; 42 bursts to go [Q: empty]
time 14543ms: Recalculated tau for process B: old tau 90ms; new tau 49ms [Q: empty]
time 14543ms: Process B switching out of CPU; will block on I/O until time 15635ms [Q: empty]
time 15635ms: Process B (tau 49ms) completed I/O; added to ready queue [Q: B]
time 15637ms: Process B (tau 49ms) started using the CPU for 95ms burst [Q: empty]
time 15732ms: Process B (tau 49ms) completed a CPU burst; 41 bursts to go [Q: empty]
time 15732ms: Recalculated tau for process B: old tau 49ms; new tau 72ms [Q: empty]
time 15732ms: Process B switching out of CPU; will block on I/O until time 17074ms [Q: empty]
time 17074ms: Process B (tau 72ms) completed I/O; added to ready queue [Q: B]
time 17076ms: Process B (tau 72ms) started using the CPU for 45ms burst [Q: empty]
time 17121ms: Process B (tau 72ms) completed a CPU burst; 40 bursts to go [Q: empty]
time 17121ms: Recalculated tau for process B: old tau 72ms; new tau 59ms [Q: empty]
time 17121ms: Process B switching out of CPU; will block on I/O until time 17833ms [Q: empty]
time 17833ms: Process B (tau 59ms) completed I/O; added to ready queue [Q: B]
time 17835ms: Process B (tau 59ms) started using the CPU for 142ms burst [Q: empty]
time 17977ms: Process B (tau 59ms) completed a CPU burst; 39 bursts to go [Q: empty]
time 17977ms: Recalculated tau for process B: old tau 59ms; new tau 101ms [Q: empty]
time 17977ms: Process B switching out of CPU; will block on I/O until time 17989ms [Q: empty]
time 17989ms: Process B (tau 101ms) completed I/O; added to ready queue [Q: B]
time 17991ms: Process B (tau 101ms) started using the CPU for 56ms burst [Q: empty]
time 18047ms: Process B (tau 101ms) completed a CPU burst; 38 bursts to go [Q: empty]
time 18047ms: Recalculated tau for process B: old tau 101ms; new tau 79ms [Q: empty]
time 18047ms: Process B switching out of CPU; will block on I/O until time 18389ms [Q: empty]
time 18389ms: Process B (tau 79ms) completed I/O; added to ready queue [Q: B]
time 18391ms: Process B (tau 79ms) started using the CPU for 6ms burst [Q: empty]
time 18397ms: Process B (tau 79ms) completed a CPU burst; 37 bursts to go [Q: empty]
time 18397ms: Recalculated tau for process B: old tau 79ms; new tau 43ms [Q: empty]
time 18397ms: Process B switching out of CPU; will block on I/O until time 23049ms [Q: empty]
time 23049ms: Process B (tau 43ms) completed I/O; added to ready queue [Q: B]
time 23051ms: Process B (tau 43ms) started using the CPU for 209ms burst [Q: empty]
time 23260ms: Process B (tau 43ms) completed a CPU burst; 36 bursts to go [Q: empty]
time 23260ms: Recalculated tau for process B: old tau 43ms; new tau 126ms [Q: empty]
time 23260ms: Process B switching out of CPU; will block on I/O until time 23342ms [Q: empty]
time 23342ms: Process B (tau 126ms) completed I/O; added to ready queue [Q: B]
time 23344ms: Process B (tau 126ms) started using the CPU for 211ms burst [Q: empty]
time 23555ms: Process B (tau 126ms) completed a CPU burst; 35 bursts to go [Q: empty]
time 23555ms: Recalculated tau for process B: old tau 126ms; new tau 169ms [Q: empty]
time 23555ms: Process B switching out of CPU; will block on I/O until time 24617ms [Q: empty]
time 24617ms: Process B (tau 169ms) completed I/O; added to ready queue [Q: B]
time 24619ms: Process B (tau 169ms) started using the CPU for 60ms burst [Q: empty]
time 24679ms: Process B (tau 169ms) completed a CPU burst; 34 bursts to go [Q: empty]
time 24679ms: Recalculated tau for process B: old tau 169ms; new tau 115ms [Q: empty]
time 24679ms: Process B switching out of CPU; will block on I/O until time 25591ms [Q: empty]
time 25591ms: Process B (tau 115ms) completed I/O; added to ready queue [Q: B]
time 25593ms: Process B (tau 115ms) started using the CPU for 46ms burst [Q: empty]
time 25639ms: Process B (tau 115ms) completed a CPU burst; 33 bursts to go [Q: empty]
time 25639ms: Recalculated tau for process B: old tau 115ms; new tau 81ms [Q: empty]
time 25639ms: Process B switching out of CPU; will block on I/O until time 26021ms [Q: empty]
time 26021ms: Process B (tau 81ms) completed I/O; added to ready queue [Q: B]
time 26023ms: Process B (tau 81ms) started using the CPU for 4ms burst [Q: empty]
time 26027ms: Process B (tau 81ms) completed a CPU burst; 32 bursts to go [Q: empty]
time 26027ms: Recalculated tau for process B: old tau 81ms; new tau 43ms [Q: empty]
time 26027ms: Process B switching out of CPU; will block on I/O until time 26179ms [Q: empty]
time 26179ms: Process B (tau 43ms) completed I/O; added to ready queue [Q: B]
time 26181ms: Process B (tau 43ms) started using the CPU for 6ms burst [Q: empty]
time 26187ms: Process B (tau 43ms) completed a CPU burst; 31 bursts to go [Q: empty]
time 26187ms: Recalculated tau for process B: old tau 43ms; new tau 25ms [Q: empty]
time 26187ms: Process B switching out of CPU; will block on I/O until time 27279ms [Q: empty]
time 27279ms: Process B (tau 25ms) completed I/O; added to ready queue [Q: B]
time 27281ms: Process B (tau 25ms) started using the CPU for 24ms burst [Q: empty]
time 27305ms: Process B (tau 25ms) completed a CPU burst; 30 bursts to go [Q: empty]
time 27305ms: Recalculated tau for process B: old tau 25ms; new tau 25ms [Q: empty]
time 27305ms: Process B switching out of CPU; will block on I/O until time 27947ms [Q: empty]
time 27947ms: Process B (tau 25ms) completed I/O; added to ready queue [Q: B]
time 27949ms: Process B (tau 25ms) started using the CPU for 101ms burst [Q: empty]
time 28050ms: Process B (tau 25ms) completed a CPU burst; 29 bursts to go [Q: empty]
time 28050ms: Recalculated tau for process B: old tau 25ms; new tau 63ms [Q: empty]
time 28050ms: Process B switching out of CPU; will block on I/O until time 28962ms [Q: empty]
time 28962ms: Process B (tau 63ms) completed I/O; added to ready queue [Q: B]
time 28964ms: Process B (tau 63ms) started using the CPU for 98ms burst [Q: empty]
time 29062ms: Process B (tau 63ms) completed a CPU burst; 28 bursts to go [Q: empty]
time 29062ms: Recalculated tau for process B: old tau 63ms; new tau 81ms [Q: empty]
time 29062ms: Process B switching out of CPU; will block on I/O until time 31574ms [Q: empty]
time 31574ms: Process B (tau 81ms) completed I/O; added to ready queue [Q: B]
time 31576ms: Process B (tau 81ms) started using the CPU for 78ms burst [Q: empty]
time 31654ms: Process B (tau 81ms) completed a CPU burst; 27 bursts to go [Q: empty]
time 31654ms: Recalculated tau for process B: old tau 81ms; new tau 80ms [Q: empty]
time 31654ms: Process B switching out of CPU; will block on I/O until time 32716ms [Q: empty]
time 32716ms: Process B (tau 80ms) completed I/O; added to ready queue [Q: B]
time 32718ms: Process B (tau 80ms) started using the CPU for 49ms burst [Q: empty]
time 32767ms: Process B (tau 80ms) completed a CPU burst; 26 bursts to go [Q: empty]
time 32767ms: Recalculated tau for process B: old tau 80ms; new tau 65ms [Q: empty]
time 32767ms: Process B switching out of CPU; will block on I/O until time 35739ms [Q: empty]
time 35739ms: Process B (tau 65ms) completed I/O; added to ready queue [Q: B]
time 35741ms: Process B (tau 65ms) started using the CPU for 93ms burst [Q: empty]
time 35834ms: Process B (tau 65ms) completed a CPU burst; 25 bursts to go [Q: empty]
time 35834ms: Recalculated tau for process B: old tau 65ms; new tau 79ms [Q: empty]
time 35834ms: Process B switching out of CPU; will block on I/O until time 37026ms [Q: empty]
time 37026ms: Process B (tau 79ms) completed I/O; added to ready queue [Q: B]
time 37028ms: Process B (tau 79ms) started using the CPU for 347ms burst [Q: empty]
time 37375ms: Process B (tau 79ms) completed a CPU burst; 24 bursts to go [Q: empty]
time 37375ms: Recalculated tau for process B: old tau 79ms; new tau 213ms [Q: empty]
time 37375ms: Process B switching out of CPU; will block on I/O until time 37617ms [Q: empty]
time 37617ms: Process B (tau 213ms) completed I/O; added to ready queue [Q: B]
time 37619ms: Process B (tau 213ms) started using the CPU for 80ms burst [Q: empty]
time 37699ms: Process B (tau 213ms) completed a CPU burst; 23 bursts to go [Q: empty]
time 37699ms: Recalculated tau for process B: old tau 213ms; new tau 147ms [Q: empty]
time 37699ms: Process B switching out of CPU; will block on I/O until time 40461ms [Q: empty]
time 40461ms: Process B (tau 147ms) completed I/O; added to ready queue [Q: B]
time 40463ms: Process B (tau 147ms) started using the CPU for 182ms burst [Q: empty]
time 40645ms: Process B (tau 147ms) completed a CPU burst; 22 bursts to go [Q: empty]
time 40645ms: Recalculated tau for process B: old tau 147ms; new tau 165ms [Q: empty]
time 40645ms: Process B switching out of CPU; will block on I/O until time 40877ms [Q: empty]
time 40877ms: Process B (tau 165ms) completed I/O; added to ready queue [Q: B]
time 40879ms: Process B (tau 165ms) started using the CPU for 415ms burst [Q: empty]
time 41294ms: Process B (tau 165ms) completed a CPU burst; 21 bursts to go [Q: empty]
time 41294ms: Recalculated tau for process B: old tau 165ms; new tau 290ms [Q: empty]
time 41294ms: Process B switching out of CPU; will block on I/O until time 42216ms [Q: empty]
time 42216ms: Process B (tau 290ms) completed I/O; added to ready queue [Q: B]
time 42218ms: Process B (tau 290ms) started using the CPU for 281ms burst [Q: empty]
time 42499ms: Process B (tau 290ms) completed a CPU burst; 20 bursts to go [Q: empty]
time 42499ms: Recalculated tau for process B: old tau 290ms; new tau 286ms [Q: empty]
time 42499ms: Process B switching out of CPU; will block on I/O until time 43121ms [Q: empty]
time 43121ms: Process B (tau 286ms) completed I/O; added to ready queue [Q: B]
time 43123ms: Process B (tau 286ms) started using the CPU for 77ms burst [Q: empty]
time 43200ms: Process B (tau 286ms) completed a CPU burst; 19 bursts to go [Q: empty]
time 43200ms: Recalculated tau for process B: old tau 286ms; new tau 182ms [Q: empty]
time 43200ms: Process B switching out of CPU; will block on I/O until time 43782ms [Q: empty]
time 43782ms: Process B (tau 182ms) completed I/O; added to ready queue [Q: B]
time 43784ms: Process B (tau 182ms) started using the CPU for 56ms burst [Q: empty]
time 43840ms: Process B (tau 182ms) completed a CPU burst; 18 bursts to go [Q: empty]
time 43840ms: Recalculated tau for process B: old tau 182ms; new tau 119ms [Q: empty]
time 43840ms: Process B switching out of CPU; will block on I/O until time 44502ms [Q: empty]
time 44502ms: Process B (tau 119ms) completed I/O; added to ready queue [Q: B]
time 44504ms: Process B (tau 119ms) started using the CPU for 53ms burst [Q: empty]
time 44557ms: Process B (tau 119ms) completed a CPU burst; 17 bursts to go [Q: empty]
time 44557ms: Recalculated tau for process B: old tau 119ms; new tau 86ms [Q: empty]
time 44557ms: Process B switching out of CPU; will block on I/O until time 44869ms [Q: empty]
time 44869ms: Process B (tau 86ms) completed I/O; added to ready queue [Q: B]
time 44871ms: Process B (tau 86ms) started using the CPU for 77ms burst [Q: empty]
time 44948ms: Process B (tau 86ms) completed a CPU burst; 16 bursts to go [Q: empty]
time 44948ms: Recalculated tau for process B: old tau 86ms; new tau 82ms [Q: empty]
time 44948ms: Process B switching out of CPU; will block on I/O until time 46060ms [Q: empty]
time 46060ms: Process B (tau 82ms) completed I/O; added to ready queue [Q: B]
time 46062ms: Process B (tau 82ms) started using the CPU for 197ms burst [Q: empty]
time 46259ms: Process B (tau 82ms) completed a CPU burst; 15 bursts to go [Q: empty]
time 46259ms: Recalculated tau for process B: old tau 82ms; new tau 140ms [Q: empty]
time 46259ms: Process B switching out of CPU; will block on I/O until time 47851ms [Q: empty]
time 47851ms: Process B (tau 140ms) completed I/O; added to ready queue [Q: B]
time 47853ms: Process B (tau 140ms) started using the CPU for 5ms burst [Q: empty]
time 47858ms: Process B (tau 140ms) completed a CPU burst; 14 bursts to go [Q: empty]
time 47858ms: Recalculated tau for process B: old tau 140ms; new tau 73ms [Q: empty]
time 47858ms: Process B switching out of CPU; will block on I/O until time 48230ms [Q: empty]
time 48230ms: Process B (tau 73ms) completed I/O; added to ready queue [Q: B]
time 48232ms: Process B (tau 73ms) started using the CPU for 65ms burst [Q: empty]
time 48297ms: Process B (tau 73ms) completed a CPU burst; 13 bursts to go [Q: empty]
time 48297ms: Recalculated tau for process B: old tau 73ms; new tau 69ms [Q: empty]
time 48297ms: Process B switching out of CPU; will block on I/O until time 48869ms [Q: empty]
time 48869ms: Process B (tau 69ms) completed I/O; added to ready queue [Q: B]
time 48871ms: Process B (tau 69ms) started using the CPU for 39ms burst [Q: empty]
time 48910ms: Process B (tau 69ms) completed a CPU burst; 12 bursts to go [Q: empty]
time 48910ms: Recalculated tau for process B: old tau 69ms; new tau 54ms [Q: empty]
time 48910ms: Process B switching out of CPU; will block on I/O until time 49982ms [Q: empty]
time 49982ms: Process B (tau 54ms) completed I/O; added to ready queue [Q: B]
time 49984ms: Process B (tau 54ms) started using the CPU for 37ms burst [Q: empty]
time 50021ms: Process B (tau 54ms) completed a CPU burst; 11 bursts to go [Q: empty]
time 50021ms: Recalculated tau for process B: old tau 54ms; new tau 46ms [Q: empty]
time 50021ms: Process B switching out of CPU; will block on I/O until time 50393ms [Q: empty]
time 50393ms: Process B (tau 46ms) completed I/O; added to ready queue [Q: B]
time 50395ms: Process B (tau 46ms) started using the CPU for 49ms burst [Q: empty]
time 50444ms: Process B (tau 46ms) completed a CPU burst; 10 bursts to go [Q: empty]
time 50444ms: Recalculated tau for process B: old tau 46ms; new tau 48ms [Q: empty]
time 50444ms: Process B switching out of CPU; will block on I/O until time 50576ms [Q: empty]
time 50576ms: Process B (tau 48ms) completed I/O; added to ready queue [Q: B]
time 50578ms: Process B (tau 48ms) started using the CPU for 4ms burst [Q: empty]
time 50582ms: Process B (tau 48ms) completed a CPU burst; 9 bursts to go [Q: empty]
time 50582ms: Recalculated tau for process B: old tau 48ms; new tau 26ms [Q: empty]
time 50582ms: Process B switching out of CPU; will block on I/O until time 51474ms [Q: empty]
time 51474ms: Process B (tau 26ms) completed I/O; added to ready queue [Q: B]
time 51476ms: Process B (tau 26ms) started using the CPU for 3ms burst [Q: empty]
time 51479ms: Process B (tau 26ms) completed a CPU burst; 8 bursts to go [Q: empty]
time 51479ms: Recalculated tau for process B: old tau 26ms; new tau 15ms [Q: empty]
time 51479ms: Process B switching out of CPU; will block on I/O until time 51981ms [Q: empty]
time 51981ms: Process B (tau 15ms) completed I/O; added to ready queue [Q: B]
time 51983ms: Process B (tau 15ms) started using the CPU for 219ms burst [Q: empty]
time 52202ms: Process B (tau 15ms) completed a CPU burst; 7 bursts to go [Q: empty]
time 52202ms: Recalculated tau for process B: old tau 15ms; new tau 117ms [Q: empty]
time 52202ms: Process B switching out of CPU; will block on I/O until time 55004ms [Q: empty]
time 55004ms: Process B (tau 117ms) completed I/O; added to ready queue [Q: B]
time 55006ms: Process B (tau 117ms) started using the CPU for 24ms burst [Q: empty]
time 55030ms: Process B (tau 117ms) completed a CPU burst; 6 bursts to go [Q: empty]
time 55030ms: Recalculated tau for process B: old tau 117ms; new tau 71ms [Q: empty]
time 55030ms: Process B switching out of CPU; will block on I/O until time 56312ms [Q: empty]
time 56312ms: Process B (tau 71ms) completed I/O; added to ready queue [Q: B]
time 56314ms: Process B (tau 71ms) started using the CPU for 230ms burst [Q: empty]
time 56544ms: Process B (tau 71ms) completed a CPU burst; 5 bursts to go [Q: empty]
time 56544ms: Recalculated tau for process B: old tau 71ms; new tau 151ms [Q: empty]
time 56544ms: Process B switching out of CPU; will block on I/O until time 57146ms [Q: empty]
time 57146ms: Process B (tau 151ms) completed I/O; added to ready queue [Q: B]
time 57148ms: Process B (tau 151ms) started using the CPU for 26ms burst [Q: empty]
time 57174ms: Process B (tau 151ms) completed a CPU burst; 4 bursts to go [Q: empty]
time 57174ms: Recalculated tau for process B: old tau 151ms; new tau 89ms [Q: empty]
time 57174ms: Process B switching out of CPU; will block on I/O until time 58136ms [Q: empty]
time 58136ms: Process B (tau 89ms) completed I/O; added to ready queue [Q: B]
time 58138ms: Process B (tau 89ms) started using the CPU for 13ms burst [Q: empty]
time 58151ms: Process B (tau 89ms) completed a CPU burst; 3 bursts to go [Q: empty]
time 58151ms: Recalculated tau for process B: old tau 89ms; new tau 51ms [Q: empty]
time 58151ms: Process B switching out of CPU; will block on I/O until time 58683ms [Q: empty]
time 58683ms: Process B (tau 51ms) completed I/O; added to ready queue [Q: B]
time 58685ms: Process B (tau 51ms) started using the CPU for 163ms burst [Q: empty]
time 58848ms: Process B (tau 51ms) completed a CPU burst; 2 bursts to go [Q: empty]
time 58848ms: Recalculated tau for process B: old tau 51ms; new tau 107ms [Q: empty]
time 58848ms: Process B switching out of CPU; will block on I/O until time 59270ms [Q: empty]
time 59270ms: Process B (tau 107ms) completed I/O; added to ready queue [Q: B]
time 59272ms: Process B (tau 107ms) started using the CPU for 11ms burst [Q: empty]
time 59283ms: Process B (tau 107ms) completed a CPU burst; 1 bursts to go [Q: empty]
time 59283ms: Recalculated tau for process B: old tau 107ms; new tau 59ms [Q: empty]
time 59283ms: Process B switching out of CPU; will block on I/O until time 59705ms [Q: empty]
time 59705ms: Process B (tau 59ms) completed I/O; added to ready queue [Q: B]
time 59707ms: Process B (tau 59ms) started using the CPU for 158ms burst [Q: empty]
time 59865ms: Process B terminated [Q: empty]
time 59867ms: Simulator ended for SJF [Q: empty]

time 0ms: Simulator started for RR with time slice 64ms [Q: empty]
time 33ms: Process A arrived; added to ready queue [Q: A]
time 35ms: Process A started using the CPU for 207ms burst [Q: empty]
time 91ms: Process B arrived; added to ready queue [Q: B]
time 99ms: Time slice expired; process A preempted with 143ms remaining [Q: B]
time 103ms: Process B started using the CPU for 70ms burst [Q: A]
time 167ms: Time slice expired; process B preempted with 6ms remaining [Q: A]
time 171ms: Process A started using the CPU for remaining 143ms of 207ms burst [Q: B]
time 235ms: Time slice expired; process A preempted with 79ms remaining [Q: B]
time 239ms: Process B started using the CPU for remaining 6ms of 70ms burst [Q: A]
time 245ms: Process B completed a CPU burst; 57 bursts to go [Q: A]
time 245ms: Process B switching out of CPU; will block on I/O until time 2827ms [Q: A]
time 249ms: Process A started using the CPU for remaining 79ms of 207ms burst [Q: empty]
time 313ms: Time slice expired; no preemption because ready queue is empty [Q: empty]
time 328ms: Process A completed a CPU burst; 13 bursts to go [Q: empty]
time 328ms: Process A switching out of CPU; will block on I/O until time 670ms [Q: empty]
time 670ms: Process A completed I/O; added to ready queue [Q: A]
time 672ms: Process A started using the CPU for 105ms burst [Q: empty]
time 736ms: Time slice expired; no preemption because ready queue is empty [Q: empty]
time 777ms: Process A completed a CPU burst; 12 bursts to go [Q: empty]
time 777ms: Process A switching out of CPU; will block on I/O until time 899ms [Q: empty]
time 899ms: Process A completed I/O; added to ready queue [Q: A]
time 901ms: Process A started using the CPU for 226ms burst [Q: empty]
time 965ms: Time slice expired; no preemption because ready queue is empty [Q: empty]
time 1029ms: Time slice expired; no preemption because ready queue is empty [Q: empty]
time 1093ms: Time slice expired; no preemption because ready queue is empty [Q: empty]
time 1127ms: Process A completed a CPU burst; 11 bursts to go [Q: empty]
time 1127ms: Process A switching out of CPU; will block on I/O until time 2849ms [Q: empty]
time 2827ms: Process B completed I/O; added to ready queue [Q: B]
time 2829ms: Process B started using the CPU for 8ms burst [Q: empty]
time 2837ms: Process B completed a CPU burst; 56 bursts to go [Q: empty]
time 2837ms: Process B switching out of CPU; will block on I/O until time 3309ms [Q: empty]
time 2849ms: Process A completed I/O; added to ready queue [Q: A]
time 2851ms: Process A started using the CPU for 64ms burst [Q: empty]
time 2915ms: Process A completed a CPU burst; 10 bursts to go [Q: empty]
time 2915ms: Process A switching out of CPU; will block on I/O until time 3527ms [Q: empty]
time 3309ms: Process B completed I/O; added to ready queue [Q: B]
time 3311ms: Process B started using the CPU for 15ms burst [Q: empty]
time 3326ms: Process B completed a CPU burst; 55 bursts to go [Q: empty]
time 3326ms: Process B switching out of CPU; will block on I/O until time 3608ms [Q: empty]
time 3527ms: Process A completed I/O; added to ready queue [Q: A]
time 3529ms: Process A started using the CPU for 44ms burst [Q: empty]
time 3573ms: Process A completed a CPU burst; 9 bursts to go [Q: empty]
time 3573ms: Process A switching out of CPU; will block on I/O until time 4225ms [Q: empty]
time 3608ms: Process B completed I/O; added to ready queue [Q: B]
time 3610ms: Process B started using the CPU for 71ms burst [Q: empty]
time 3674ms: Time slice expired; no preemption because ready queue is empty [Q: empty]
time 3681ms: Process B completed a CPU burst; 54 bursts to go [Q: empty]
time 3681ms: Process B switching out of CPU; will block on I/O until time 3963ms [Q: empty]
time 3963ms: Process B completed I/O; added to ready queue [Q: B]
time 3965ms: Process B started using the CPU for 69ms burst [Q: empty]
time 4029ms: Time slice expired; no preemption because ready queue is empty [Q: empty]
time 4034ms: Process B completed a CPU burst; 53 bursts to go [Q: empty]
time 4034ms: Process B switching out of CPU; will block on I/O until time 4586ms [Q: empty]
time 4225ms: Process A completed I/O; added to ready queue [Q: A]
time 4227ms: Process A started using the CPU for 110ms burst [Q: empty]
time 4291ms: Time slice expired; no preemption because ready queue is empty [Q: empty]
time 4337ms: Process A completed a CPU burst; 8 bursts to go [Q: empty]
time 4337ms: Process A switching out of CPU; will block on I/O until time 4969ms [Q: empty]
time 4586ms: Process B completed I/O; added to ready queue [Q: B]
time 4588ms: Process B started using the CPU for 31ms burst [Q: empty]
time 4619ms: Process B completed a CPU burst; 52 bursts to go [Q: empty]
time 4619ms: Process B switching out of CPU; will block on I/O until time 6111ms [Q: empty]
time 4969ms: Process A completed I/O; added to ready queue [Q: A]
time 4971ms: Process A started using the CPU for 4ms burst [Q: empty]
time 4975ms: Process A completed a CPU burst; 7 bursts to go [Q: empty]
time 4975ms: Process A switching out of CPU; will block on I/O until time 5047ms [Q: empty]
time 5047ms: Process A completed I/O; added to ready queue [Q: A]
time 5049ms: Process A started using the CPU for 11ms burst [Q: empty]
time 5060ms: Process A completed a CPU burst; 6 bursts to go [Q: empty]
time 5060ms: Process A switching out of CPU; will block on I/O until time 5352ms [Q: empty]
time 5352ms: Process A completed I/O; added to ready queue [Q: A]
time 5354ms: Process A started using the CPU for 82ms burst [Q: empty]
time 5418ms: Time slice expired; no preemption because ready queue is empty [Q: empty]
time 5436ms: Process A completed a CPU burst; 5 bursts to go [Q: empty]
time 5436ms: Process A switching out of CPU; will block on I/O until time 7188ms [Q: empty]
time 6111ms: Process B completed I/O; added to ready queue [Q: B]
time 6113ms: Process B started using the CPU for 61ms burst [Q: empty]
time 6174ms: Process B completed a CPU burst; 51 bursts to go [Q: empty]
time 6174ms: Process B switching out of CPU; will block on I/O until time 6286ms [Q: empty]
time 6286ms: Process B completed I/O; added to ready queue [Q: B]
time 6288ms: Process B started using the CPU for 73ms burst [Q: empty]
time 6352ms: Time slice expired; no preemption because ready queue is empty [Q: empty]
time 6361ms: Process B completed a CPU burst; 50 bursts to go [Q: empty]
time 6361ms: Process B switching out of CPU; will block on I/O until time 6603ms [Q: empty]
time 6603ms: Process B completed I/O; added to ready queue [Q: B]
time 6605ms: Process B started using the CPU for 56ms burst [Q: empty]
time 6661ms: Process B completed a CPU burst; 49 bursts to go [Q: empty]
time 6661ms: Process B switching out of CPU; will block on I/O until time 7623ms [Q: empty]
time 7188ms: Process A completed I/O; added to ready queue [Q: A]
time 7190ms: Process A started using the CPU for 49ms burst [Q: empty]
time 7239ms: Process A completed a CPU burst; 4 bursts to go [Q: empty]
time 7239ms: Process A switching out of CPU; will block on I/O until time 10821ms [Q: empty]
time 7623ms: Process B completed I/O; added to ready queue [Q: B]
time 7625ms: Process B started using the CPU for 32ms burst [Q: empty]
time 7657ms: Process B completed a CPU burst; 48 bursts to go [Q: empty]
time 7657ms: Process B switching out of CPU; will block on I/O until time 9269ms [Q: empty]
time 9269ms: Process B completed I/O; added to ready queue [Q: B]
time 9271ms: Process B started using the CPU for 79ms burst [Q: empty]
time 9335ms: Time slice expired; no preemption because ready queue is empty [Q: empty]
time 9350ms: Process B completed a CPU burst; 47 bursts to go [Q: empty]
time 9350ms: Process B switching out of CPU; will block on I/O until time 9392ms [Q: empty]
time 9392ms: Process B completed I/O; added to ready queue [Q: B]
time 9394ms: Process B started using the CPU for 70ms burst [Q: empty]
time 9458ms: Time slice expired; no preemption because ready queue is empty [Q: empty]
time 9464ms: Process B completed a CPU burst; 46 bursts to go [Q: empty]
time 9464ms: Process B switching out of CPU; will block on I/O until time 11536ms [Q: empty]
time 10821ms: Process A completed I/O; added to ready queue [Q: A]
time 10823ms: Process A started using the CPU for 117ms burst [Q: empty]
time 10887ms: Time slice expired; no preemption because ready queue is empty [Q: empty]
time 10940ms: Process A completed a CPU burst; 3 bursts to go [Q: empty]
time 10940ms: Process A switching out of CPU; will block on I/O until time 11102ms [Q: empty]
time 11102ms: Process A completed I/O; added to ready queue [Q: A]
time 11104ms: Process A started using the CPU for 73ms burst [Q: empty]
time 11168ms: Time slice expired; no preemption because ready queue is empty [Q: empty]
time 11177ms: Process A completed a CPU burst; 2 bursts to go [Q: empty]
time 11177ms: Process A switching out of CPU; will block on I/O until time 12779ms [Q: empty]
time 11536ms: Process B completed I/O; added to ready queue [Q: B]
time 11538ms: Process B started using the CPU for 103ms burst [Q: empty]
time 11602ms: Time slice expired; no preemption because ready queue is empty [Q: empty]
time 11641ms: Process B completed a CPU burst; 45 bursts to go [Q: empty]
time 11641ms: Process B switching out of CPU; will block on I/O until time 13393ms [Q: empty]
time 12779ms: Process A completed I/O; added to ready queue [Q: A]
time 12781ms: Process A started using the CPU for 117ms burst [Q: empty]
time 12845ms: Time slice expired; no preemption because ready queue is empty [Q: empty]
time 12898ms: Process A completed a CPU burst; 1 bursts to go [Q: empty]
time 12898ms: Process A switching out of CPU; will block on I/O until time 13970ms [Q: empty]
time 13393ms: Process B completed I/O; added to ready queue [Q: B]
time 13395ms: Process B started using the CPU for 148ms burst [Q: empty]
time 13459ms: Time slice expired; no preemption because ready queue is empty [Q: empty]
time 13523ms: Time slice expired; no preemption because ready queue is empty [Q: empty]
time 13543ms: Process B completed a CPU burst; 44 bursts to go [Q: empty]
time 13543ms: Process B switching out of CPU; will block on I/O until time 14305ms [Q: empty]
time 13970ms: Process A completed I/O; added to ready queue [Q: A]
time 13972ms: Process A started using the CPU for 69ms burst [Q: empty]
time 14036ms: Time slice expired; no preemption because ready queue is empty [Q: empty]
time 14041ms: Process A terminated [Q: empty]
time 14305ms: Process B completed I/O; added to ready queue [Q: B]
time 14307ms: Process B started using the CPU for 63ms burst [Q: empty]
time 14370ms: Process B completed a CPU burst; 43 bursts to go [Q: empty]
time 14370ms: Process B switching out of CPU; will block on I/O until time 14462ms [Q: empty]
time 14462ms: Process B completed I/O; added to ready queue [Q: B]
time 14464ms: Process B started using the CPU for 8ms burst [Q: empty]
time 14472ms: Process B completed a CPU burst; 42 bursts to go [Q: empty]
time 14472ms: Process B switching out of CPU; will block on I/O until time 15564ms [Q: empty]
time 15564ms: Process B completed I/O; added to ready queue [Q: B]
time 15566ms: Process B started using the CPU for 95ms burst [Q: empty]
time 15630ms: Time slice expired; no preemption because ready queue is empty [Q: empty]
time 15661ms: Process B completed a CPU burst; 41 bursts to go [Q: empty]
time 15661ms: Process B switching out of CPU; will block on I/O until time 17003ms [Q: empty]
time 17003ms: Process B completed I/O; added to ready queue [Q: B]
time 17005ms: Process B started using the CPU for 45ms burst [Q: empty]
time 17050ms: Process B completed a CPU burst; 40 bursts to go [Q: empty]
time 17050ms: Process B switching out of CPU; will block on I/O until time 17762ms [Q: empty]
time 17762ms: Process B completed I/O; added to ready queue [Q: B]
time 17764ms: Process B started using the CPU for 142ms burst [Q: empty]
time 17828ms: Time slice expired; no preemption because ready queue is empty [Q: empty]
time 17892ms: Time slice expired; no preemption because ready queue is empty [Q: empty]
time 17906ms: Process B completed a CPU burst; 39 bursts to go [Q: empty]
time 17906ms: Process B switching out of CPU; will block on I/O until time 17918ms [Q: empty]
time 17918ms: Process B completed I/O; added to ready queue [Q: B]
time 17920ms: Process B started using the CPU for 56ms burst [Q: empty]
time 17976ms: Process B completed a CPU burst; 38 bursts to go [Q: empty]
time 17976ms: Process B switching out of CPU; will block on I/O until time 18318ms [Q: empty]
time 18318ms: Process B completed I/O; added to ready queue [Q: B]
time 18320ms: Process B started using the CPU for 6ms burst [Q: empty]
time 18326ms: Process B completed a CPU burst; 37 bursts to go [Q: empty]
time 18326ms: Process B switching out of CPU; will block on I/O until time 22978ms [Q: empty]
time 22978ms: Process B completed I/O; added to ready queue [Q: B]
time 22980ms: Process B started using the CPU for 209ms burst [Q: empty]
time 23044ms: Time slice expired; no preemption because ready queue is empty [Q: empty]
time 23108ms: Time slice expired; no preemption because ready queue is empty [Q: empty]
time 23172ms: Time slice expired; no preemption because ready queue is empty [Q: empty]
time 23189ms: Process B completed a CPU burst; 36 bursts to go [Q: empty]
time 23189ms: Process B switching out of CPU; will block on I/O until time 23271ms [Q: empty]
time 23271ms: Process B completed I/O; added to ready queue [Q: B]
time 23273ms: Process B started using the CPU for 211ms burst [Q: empty]
time 23337ms: Time slice expired; no preemption because ready queue is empty [Q: empty]
time 23401ms: Time slice expired; no preemption because ready queue is empty [Q: empty]
time 23465ms: Time slice expired; no preemption because ready queue is empty [Q: empty]
time 23484ms: Process B completed a CPU burst; 35 bursts to go [Q: empty]
time 23484ms: Process B switching out of CPU; will block on I/O until time 24546ms [Q: empty]
time 24546ms: Process B completed I/O; added to ready queue [Q: B]
time 24548ms: Process B started using the CPU for 60ms burst [Q: empty]
time 24608ms: Process B completed a CPU burst; 34 bursts to go [Q: empty]
time 24608ms: Process B switching out of CPU; will block on I/O until time 25520ms [Q: empty]
time 25520ms: Process B completed I/O; added to ready queue [Q: B]
time 25522ms: Process B started using the CPU for 46ms burst [Q: empty]
time 25568ms: Process B completed a CPU burst; 33 bursts to go [Q: empty]
time 25568ms: Process B switching out of CPU; will block on I/O until time 25950ms [Q: empty]
time 25950ms: Process B completed I/O; added to ready queue [Q: B]
time 25952ms: Process B started using the CPU for 4ms burst [Q: empty]
time 25956ms: Process B completed a CPU burst; 32 bursts to go [Q: empty]
time 25956ms: Process B switching out of CPU; will block on I/O until time 26108ms [Q: empty]
time 26108ms: Process B completed I/O; added to ready queue [Q: B]
time 26110ms: Process B started using the CPU for 6ms burst [Q: empty]
time 26116ms: Process B completed a CPU burst; 31 bursts to go [Q: empty]
time 26116ms: Process B switching out of CPU; will block on I/O until time 27208ms [Q: empty]
time 27208ms: Process B completed I/O; added to ready queue [Q: B]
time 27210ms: Process B started using the CPU for 24ms burst [Q: empty]
time 27234ms: Process B completed a CPU burst; 30 bursts to go [Q: empty]
time 27234ms: Process B switching out of CPU; will block on I/O until time 27876ms [Q: empty]
time 27876ms: Process B completed I/O; added to ready queue [Q: B]
time 27878ms: Process B started using the CPU for 101ms burst [Q: empty]
time 27942ms: Time slice expired; no preemption because ready queue is empty [Q: empty]
time 27979ms: Process B completed a CPU burst; 29 bursts to go [Q: empty]
time 27979ms: Process B switching out of CPU; will block on I/O until time 28891ms [Q: empty]
time 28891ms: Process B completed I/O; added to ready queue [Q: B]
time 28893ms: Process B started using the CPU for 98ms burst [Q: empty]
time 28957ms: Time slice expired; no preemption because ready queue is empty [Q: empty]
time 28991ms: Process B completed a CPU burst; 28 bursts to go [Q: empty]
time 28991ms: Process B switching out of CPU; will block on I/O until time 31503ms [Q: empty]
time 31503ms: Process B completed I/O; added to ready queue [Q: B]
time 31505ms: Process B started using the CPU for 78ms burst [Q: empty]
time 31569ms: Time slice expired; no preemption because ready queue is empty [Q: empty]
time 31583ms: Process B completed a CPU burst; 27 bursts to go [Q: empty]
time 31583ms: Process B switching out of CPU; will block on I/O until time 32645ms [Q: empty]
time 32645ms: Process B completed I/O; added to ready queue [Q: B]
time 32647ms: Process B started using the CPU for 49ms burst [Q: empty]
time 32696ms: Process B completed a CPU burst; 26 bursts to go [Q: empty]
time 32696ms: Process B switching out of CPU; will block on I/O until time 35668ms [Q: empty]
time 35668ms: Process B completed I/O; added to ready queue [Q: B]
time 35670ms: Process B started using the CPU for 93ms burst [Q: empty]
time 35734ms: Time slice expired; no preemption because ready queue is empty [Q: empty]
time 35763ms: Process B completed a CPU burst; 25 bursts to go [Q: empty]
time 35763ms: Process B switching out of CPU; will block on I/O until time 36955ms [Q: empty]
time 36955ms: Process B completed I/O; added to ready queue [Q: B]
time 36957ms: Process B started using the CPU for 347ms burst [Q: empty]
time 37021ms: Time slice expired; no preemption because ready queue is empty [Q: empty]
time 37085ms: Time slice expired; no preemption because ready queue is empty [Q: empty]
time 37149ms: Time slice expired; no preemption because ready queue is empty [Q: empty]
time 37213ms: Time slice expired; no preemption because ready queue is empty [Q: empty]
time 37277ms: Time slice expired; no preemption because ready queue is empty [Q: empty]
time 37304ms: Process B completed a CPU burst; 24 bursts to go [Q: empty]
time 37304ms: Process B switching out of CPU; will block on I/O until time 37546ms [Q: empty]
time 37546ms: Process B completed I/O; added to ready queue [Q: B]
time 37548ms: Process B started using the CPU for 80ms burst [Q: empty]
time 37612ms: Time slice expired; no preemption because ready queue is empty [Q: empty]
time 37628ms: Process B completed a CPU burst; 23 bursts to go [Q: empty]
time 37628ms: Process B switching out of CPU; will block on I/O until time 40390ms [Q: empty]
time 40390ms: Process B completed I/O; added to ready queue [Q: B]
time 40392ms: Process B started using the CPU for 182ms burst [Q: empty]
time 40456ms: Time slice expired; no preemption because ready queue is empty [Q: empty]
time 40520ms: Time slice expired; no preemption because ready queue is empty [Q: empty]
time 40574ms: Process B completed a CPU burst; 22 bursts to go [Q: empty]
time 40574ms: Process B switching out of CPU; will block on I/O until time 40806ms [Q: empty]
time 40806ms: Process B completed I/O; added to ready queue [Q: B]
time 40808ms: Process B started using the CPU for 415ms burst [Q: empty]
time 40872ms: Time slice expired; no preemption because ready queue is empty [Q: empty]
time 40936ms: Time slice expired; no preemption because ready queue is empty [Q: empty]
time 41000ms: Time slice expired; no preemption because ready queue is empty [Q: empty]
time 41064ms: Time slice expired; no preemption because ready queue is empty [Q: empty]
time 41128ms: Time slice expired; no preemption because ready queue is empty [Q: empty]
time 41192ms: Time slice expired; no preemption because ready queue is empty [Q: empty]
time 41223ms: Process B completed a CPU burst; 21 bursts to go [Q: empty]
time 41223ms: Process B switching out of CPU; will block on I/O until time 42145ms [Q: empty]
time 42145ms: Process B completed I/O; added to ready queue [Q: B]
time 42147ms: Process B started using the CPU for 281ms burst [Q: empty]
time 42211ms: Time slice expired; no preemption because ready queue is empty [Q: empty]
time 42275ms: Time slice expired; no preemption because ready queue is empty [Q: empty]
time 42339ms: Time slice expired; no preemption because ready queue is empty [Q: empty]
time 42403ms: Time slice expired; no preemption because ready queue is empty [Q: empty]
time 42428ms: Process B completed a CPU burst; 20 bursts to go [Q: empty]
time 42428ms: Process B switching out of CPU; will block on I/O until time 43050ms [Q: empty]
time 43050ms: Process B completed I/O; added to ready queue [Q: B]
time 43052ms: Process B started using the CPU for 77ms burst [Q: empty]
time 43116ms: Time slice expired; no preemption because ready queue is empty [Q: empty]
time 43129ms: Process B completed a CPU burst; 19 bursts to go [Q: empty]
time 43129ms: Process B switching out of CPU; will block on I/O until time 43711ms [Q: empty]
time 43711ms: Process B completed I/O; added to ready queue [Q: B]
time 43713ms: Process B started using the CPU for 56ms burst [Q: empty]
time 43769ms: Process B completed a CPU burst; 18 bursts to go [Q: empty]
time 43769ms: Process B switching out of CPU; will block on I/O until time 44431ms [Q: empty]
time 44431ms: Process B completed I/O; added to ready queue [Q: B]
time 44433ms: Process B started using the CPU for 53ms burst [Q: empty]
time 44486ms: Process B completed a CPU burst; 17 bursts to go [Q: empty]
time 44486ms: Process B switching out of CPU; will block on I/O until time 44798ms [Q: empty]
time 44798ms: Process B completed I/O; added to ready queue [Q: B]
time 44800ms: Process B started using the CPU for 77ms burst [Q: empty]
time 44864ms: Time slice expired; no preemption because ready queue is empty [Q: empty]
time 44877ms: Process B completed a CPU burst; 16 bursts to go [Q: empty]
time 44877ms: Process B switching out of CPU; will block on I/O until time 45989ms [Q: empty]
time 45989ms: Process B completed I/O; added to ready queue [Q: B]
time 45991ms: Process B started using the CPU for 197ms burst [Q: empty]
time 46055ms: Time slice expired; no preemption because ready queue is empty [Q: empty]
time 46119ms: Time slice expired; no preemption because ready queue is empty [Q: empty]
time 46183ms: Time slice expired; no preemption because ready queue is empty [Q: empty]
time 46188ms: Process B completed a CPU burst; 15 bursts to go [Q: empty]
time 46188ms: Process B switching out of CPU; will block on I/O until time 47780ms [Q: empty]
time 47780ms: Process B completed I/O; added to ready queue [Q: B]
time 47782ms: Process B started using the CPU for 5ms burst [Q: empty]
time 47787ms: Process B completed a CPU burst; 14 bursts to go [Q: empty]
time 47787ms: Process B switching out of CPU; will block on I/O until time 48159ms [Q: empty]
time 48159ms: Process B completed I/O; added to ready queue [Q: B]
time 48161ms: Process B started using the CPU for 65ms burst [Q: empty]
time 48225ms: Time slice expired; no preemption because ready queue is empty [Q: empty]
time 48226ms: Process B completed a CPU burst; 13 bursts to go [Q: empty]
time 48226ms: Process B switching out of CPU; will block on I/O until time 48798ms [Q: empty]
time 48798ms: Process B completed I/O; added to ready queue [Q: B]
time 48800ms: Process B started using the CPU for 39ms burst [Q: empty]
time 48839ms: Process B completed a CPU burst; 12 bursts to go [Q: empty]
time 48839ms: Process B switching out of CPU; will block on I/O until time 49911ms [Q: empty]
time 49911ms: Process B completed I/O; added to ready queue [Q: B]
time 49913ms: Process B started using the CPU for 37ms burst [Q: empty]
time 49950ms: Process B completed a CPU burst; 11 bursts to go [Q: empty]
time 49950ms: Process B switching out of CPU; will block on I/O until time 50322ms [Q: empty]
time 50322ms: Process B completed I/O; added to ready queue [Q: B]
time 50324ms: Process B started using the CPU for 49ms burst [Q: empty]
time 50373ms: Process B completed a CPU burst; 10 bursts to go [Q: empty]
time 50373ms: Process B switching out of CPU; will block on I/O until time 50505ms [Q: empty]
time 50505ms: Process B completed I/O; added to ready queue [Q: B]
time 50507ms: Process B started using the CPU for 4ms burst [Q: empty]
time 50511ms: Process B completed a CPU burst; 9 bursts to go [Q: empty]
time 50511ms: Process B switching out of CPU; will block on I/O until time 51403ms [Q: empty]
time 51403ms: Process B completed I/O; added to ready queue [Q: B]
time 51405ms: Process B started using the CPU for 3ms burst [Q: empty]
time 51408ms: Process B completed a CPU burst; 8 bursts to go [Q: empty]
time 51408ms: Process B switching out of CPU; will block on I/O until time 51910ms [Q: empty]
time 51910ms: Process B completed I/O; added to ready queue [Q: B]
time 51912ms: Process B started using the CPU for 219ms burst [Q: empty]
time 51976ms: Time slice expired; no preemption because ready queue is empty [Q: empty]
time 52040ms: Time slice expired; no preemption because ready queue is empty [Q: empty]
time 52104ms: Time slice expired; no preemption because ready queue is empty [Q: empty]
time 52131ms: Process B completed a CPU burst; 7 bursts to go [Q: empty]
time 52131ms: Process B switching out of CPU; will block on I/O until time 54933ms [Q: empty]
time 54933ms: Process B completed I/O; added to ready queue [Q: B]
time 54935ms: Process B started using the CPU for 24ms burst [Q: empty]
time 54959ms: Process B completed a CPU burst; 6 bursts to go [Q: empty]
time 54959ms: Process B switching out of CPU; will block on I/O until time 56241ms [Q: empty]
time 56241ms: Process B completed I/O; added to ready queue [Q: B]
time 56243ms: Process B started using the CPU for 230ms burst [Q: empty]
time 56307ms: Time slice expired; no preemption because ready queue is empty [Q: empty]
time 56371ms: Time slice expired; no preemption because ready queue is empty [Q: empty]
time 56435ms: Time slice expired; no preemption because ready queue is empty [Q: empty]
time 56473ms: Process B completed a CPU burst; 5 bursts to go [Q: empty]
time 56473ms: Process B switching out of CPU; will block on I/O until time 57075ms [Q: empty]
time 57075ms: Process B completed I/O; added to ready queue [Q: B]
time 57077ms: Process B started using the CPU for 26ms burst [Q: empty]
time 57103ms: Process B completed a CPU burst; 4 bursts to go [Q: empty]
time 57103ms: Process B switching out of CPU; will block on I/O until time 58065ms [Q: empty]
time 58065ms: Process B completed I/O; added to ready queue [Q: B]
time 58067ms: Process B started using the CPU for 13ms burst [Q: empty]
time 58080ms: Process B completed a CPU burst; 3 bursts to go [Q: empty]
time 58080ms: Process B switching out of CPU; will block on I/O until time 58612ms [Q: empty]
time 58612ms: Process B completed I/O; added to ready queue [Q: B]
time 58614ms: Process B started using the CPU for 163ms burst [Q: empty]
time 58678ms: Time slice expired; no preemption because ready queue is empty [Q: empty]
time 58742ms: Time slice expired; no preemption because ready queue is empty [Q: empty]
time 58777ms: Process B completed a CPU burst; 2 bursts to go [Q: empty]
time 58777ms: Process B switching out of CPU; will block on I/O until time 59199ms [Q: empty]
time 59199ms: Process B completed I/O; added to ready queue [Q: B]
time 59201ms: Process B started using the CPU for 11ms burst [Q: empty]
time 59212ms: Process B completed a CPU burst; 1 bursts to go [Q: empty]
time 59212ms: Process B switching out of CPU; will block on I/O until time 59634ms [Q: empty]
time 59634ms: Process B completed I/O; added to ready queue [Q: B]
time 59636ms: Process B started using the CPU for 158ms burst [Q: empty]
time 59700ms: Time slice expired; no preemption because ready queue is empty [Q: empty]
time 59764ms: Time slice expired; no preemption because ready queue is empty [Q: empty]
time 59794ms: Process B terminated [Q: empty]
time 59796ms: Simulator ended for RR [Q: empty]
